2024-04-19 20:15:39,610 ERROR [/Users/hamadayuichi/Desktop/Python/ClassBasedView/class_based_view/class_based_view/middleware.py:13] この名前は使用できません
Traceback (most recent call last):
  File "/Users/hamadayuichi/Desktop/Python/djangoenv/lib/python3.12/site-packages/django/core/handlers/base.py", line 197, in _get_response
    response = wrapped_callback(request, *callback_args, **callback_kwargs)
               ^^^^^^^^^^^^^^^^^^^^^^^^^^^^^^^^^^^^^^^^^^^^^^^^^^^^^^^^^^^^
  File "/Users/hamadayuichi/Desktop/Python/djangoenv/lib/python3.12/site-packages/django/views/generic/base.py", line 104, in view
    return self.dispatch(request, *args, **kwargs)
           ^^^^^^^^^^^^^^^^^^^^^^^^^^^^^^^^^^^^^^^
  File "/Users/hamadayuichi/Desktop/Python/djangoenv/lib/python3.12/site-packages/django/views/generic/base.py", line 143, in dispatch
    return handler(request, *args, **kwargs)
           ^^^^^^^^^^^^^^^^^^^^^^^^^^^^^^^^^
  File "/Users/hamadayuichi/Desktop/Python/djangoenv/lib/python3.12/site-packages/django/views/generic/base.py", line 226, in get
    context = self.get_context_data(**kwargs)
              ^^^^^^^^^^^^^^^^^^^^^^^^^^^^^^^
  File "/Users/hamadayuichi/Desktop/Python/ClassBasedView/class_based_view/store/views.py", line 50, in get_context_data
    raise Http404('この名前は使用できません')
django.http.response.Http404: この名前は使用できません
2024-04-19 20:15:40,347 ERROR [/Users/hamadayuichi/Desktop/Python/ClassBasedView/class_based_view/class_based_view/middleware.py:13] この名前は使用できません
Traceback (most recent call last):
  File "/Users/hamadayuichi/Desktop/Python/djangoenv/lib/python3.12/site-packages/django/core/handlers/base.py", line 197, in _get_response
    response = wrapped_callback(request, *callback_args, **callback_kwargs)
               ^^^^^^^^^^^^^^^^^^^^^^^^^^^^^^^^^^^^^^^^^^^^^^^^^^^^^^^^^^^^
  File "/Users/hamadayuichi/Desktop/Python/djangoenv/lib/python3.12/site-packages/django/views/generic/base.py", line 104, in view
    return self.dispatch(request, *args, **kwargs)
           ^^^^^^^^^^^^^^^^^^^^^^^^^^^^^^^^^^^^^^^
  File "/Users/hamadayuichi/Desktop/Python/djangoenv/lib/python3.12/site-packages/django/views/generic/base.py", line 143, in dispatch
    return handler(request, *args, **kwargs)
           ^^^^^^^^^^^^^^^^^^^^^^^^^^^^^^^^^
  File "/Users/hamadayuichi/Desktop/Python/djangoenv/lib/python3.12/site-packages/django/views/generic/base.py", line 226, in get
    context = self.get_context_data(**kwargs)
              ^^^^^^^^^^^^^^^^^^^^^^^^^^^^^^^
  File "/Users/hamadayuichi/Desktop/Python/ClassBasedView/class_based_view/store/views.py", line 50, in get_context_data
    raise Http404('この名前は使用できません')
django.http.response.Http404: この名前は使用できません
